<?xml version="1.0" encoding="utf-8"?>
<!-- This URDF was automatically created by SolidWorks to URDF Exporter! Originally created by Stephen Brawner (brawner@gmail.com) 
     Commit Version: 1.6.0-4-g7f85cfe  Build Version: 1.6.7995.38578
     For more information, please see http://wiki.ros.org/sw_urdf_exporter -->
<robot
  name="mybot">
  <!-- xyz="-0.0381 0.34769 0.032884" -->
  <link
    name="base_link">
    <inertial>
      <origin
        xyz = "0 0 0.5"
        rpy="0 0 0" />
      <mass
        value="0.93072" />
      <inertia
        ixx="0.041016"
        ixy="-1.4648E-18"
        ixz="6.1909E-20"
        iyy="0.0018491"
        iyz="0.00043466"
        izz="0.042192" />
    </inertial>
    <visual>
      <origin
        xyz="0 0 0"
        rpy="0 0 0" />
      <geometry>
        <mesh
          filename="package://mybot/meshes/base_link.STL" />
      </geometry>
      <material
        name="">
        <color
          rgba="1 1 1 1" />
      </material>
    </visual>
    <collision>
      <origin
        xyz="0 0 0"
        rpy="0 0 0" />
      <geometry>
        <mesh
          filename="package://mybot/meshes/base_link.STL" />
      </geometry>
    </collision>
  </link>
  <link
    name="fly_wheel_Link">
    <inertial>
      <origin
        xyz="1.1102E-16 0.016061 -1.6653E-16"
        rpy="0 0 0" />
      <mass
        value="1.1139" />
      <inertia
        ixx="0.0064385"
        ixy="3.4231E-18"
        ixz="6.8847E-18"
        iyy="0.012692"
        iyz="-4.2508E-19"
        izz="0.0064385" />
    </inertial>
    <visual>
      <origin
        xyz="0 0 0"
        rpy="0 0 0" />
      <geometry>
        <mesh
          filename="package://mybot/meshes/fly_wheel_Link.STL" />
      </geometry>
      <material
        name="">
        <color
          rgba="0.79216 0.81961 0.93333 1" />
      </material>
    </visual>
    <collision>
      <origin
        xyz="0 0 0"
        rpy="0 0 0" />
      <geometry>
        <mesh
          filename="package://mybot/meshes/fly_wheel_Link.STL" />
      </geometry>
    </collision>
  </link>
  <joint
    name="fly_wheel_joint"
    type="continuous">
    <origin
      xyz="-0.0381 -0.026125 0.65534"
      rpy="0 1.5018 -3.1416" />
    <parent
      link="base_link" />
    <child
      link="fly_wheel_Link" />
    <axis
      xyz="0 1 0" />
  </joint>
  <link
    name="wheel_link">
    <inertial>
      <origin
        xyz="-1.4229E-06 -1.3336E-05 -0.038081"
        rpy="0 0 0" />
      <mass
        value="2.7797" />
      <inertia
        ixx="0.13005"
        ixy="8.4658E-07"
        ixz="-7.4352E-09"
        iyy="0.13006"
        iyz="-7.7781E-09"
        izz="0.25812" />
    </inertial>
    <visual>
      <origin
        xyz="0 0 0"
        rpy="0 0 0" />
      <geometry>
        <mesh
          filename="package://mybot/meshes/wheel_link.STL" />
      </geometry>
      <material
        name="">
        <color
          rgba="0.29412 0.29412 0.29412 1" />
      </material>
    </visual>
    <collision>
      <origin
        xyz="0 0 0"
        rpy="0 0 0" />
      <geometry>
        <mesh
          filename="package://mybot/meshes/wheel_link.STL" />
      </geometry>
    </collision>
  </link>
  <joint
    name="wheel_joint"
    type="continuous">
    <origin
      xyz="0 -0.035 0.01524"
      rpy="1.5708 0.67273 1.5708" />
    <parent
      link="base_link" />
    <child
      link="wheel_link" />
    <axis
      xyz="0 0 1" />
  </joint>

  <!--Add transmission for joints of my bot here-->
  <transmission name="trans_fly_wheel_joint">
    <type>transmission_interface/SimpleTransmission</type>
    <joint name="fly_wheel_joint">
        <hardwareInterface>hardwareInterface/EffortJointInterface</hardwareInterface>
    </joint>
    <actuator name="motor_fly_wheel_joint">
        <hardwareInterface>hardware_interface/EffortJointInterface</hardwareInterface>
        <mechanicalReduction>1</mechanicalReduction>
    </actuator>
  </transmission>
  <transmission name="trans_wheel_joint">
    <type>transmission_interface/SimpleTransmission</type>
    <joint name = "wheel_joint">
        <hardwareInterface>hardwareInterface/EffortJointInterface</hardwareInterface>
    </joint>
    <actuator name="motor_wheel_joint">
        <hardwareInterface>hardware_interface/EffortJointInterface</hardwareInterface>
        <mechanicalReduction>1</mechanicalReduction>
    </actuator>
  </transmission>

  <!--Add a gazebo controller plugin here-->
  <gazebo>
    <plugin name="gazebo_ros_control" filename="libgazebo_ros_control.so">
    </plugin>
  </gazebo>
</robot>